<?xml version="1.0"?>
<robot name="tiago_right_arm">
  <link name="arm_right_1_link"/>
  <link name="arm_right_2_link"/>
  <link name="arm_right_3_link"/>
  <link name="arm_right_4_link"/>
  <link name="arm_right_5_link"/>
  <link name="arm_right_6_link"/>
  <link name="arm_right_7_link"/>
  <link name="arm_right_tool_link"/>
  <link name="base_footprint"/>
  <link name="base_link"/>
  <link name="torso_lift_link"/>
  <joint name="base_footprint_joint" type="fixed">
    <parent link="base_footprint"/>
    <child link="base_link"/>
    <origin xyz="0 0 0.0762" rpy="0 0 0"/>
  </joint>
  <joint name="torso_lift_joint" type="prismatic">
    <parent link="base_link"/>
    <child link="torso_lift_link"/>
    <origin xyz="-0.062000 0.000000 0.813000" rpy="-0.000000 -1.570796 0.000000"/>
    <axis xyz="1 0 0"/>
    <limit lower="0.0" upper="0.35" effort="2000" velocity="0.07"/>
  </joint>
  <joint name="arm_right_1_joint" type="revolute">
    <parent link="torso_lift_link"/>
    <child link="arm_right_1_link"/>
    <origin xyz="0.025560 -0.190000 -0.171000" rpy="0.000000 0.000000 -1.570796"/>
    <axis xyz="1 0 0"/>
    <limit lower="0.0" upper="2.68" effort="50" velocity="2.0"/>
  </joint>
  <joint name="arm_right_2_joint" type="revolute">
    <parent link="arm_right_1_link"/>
    <child link="arm_right_2_link"/>
    <origin xyz="0.125000 -0.019500 -0.031000" rpy="-1.570796 0.000000 0.000000"/>
    <axis xyz="1 0 0"/>
    <limit lower="-1.5" upper="1.02" effort="50" velocity="2.0"/>
  </joint>
  <joint name="arm_right_3_joint" type="revolute">
    <parent link="arm_right_2_link"/>
    <child link="arm_right_3_link"/>
    <origin xyz="0.089500 0.000000 -0.001500" rpy="-1.570796 0.000000 1.570796"/>
    <axis xyz="1 0 0"/>
    <limit lower="-3.46" upper="1.57" effort="50" velocity="2.0"/>
  </joint>
  <joint name="arm_right_4_joint" type="revolute">
    <parent link="arm_right_3_link"/>
    <child link="arm_right_4_link"/>
    <origin xyz="-0.020000 -0.027000 -0.222000" rpy="-1.570796 -1.570796 0.000000"/>
    <axis xyz="1 0 0"/>
    <limit lower="-0.32" upper="2.27" effort="50" velocity="2.0"/>
  </joint>
  <joint name="arm_right_5_joint" type="revolute">
    <parent link="arm_right_4_link"/>
    <child link="arm_right_5_link"/>
    <origin xyz="-0.162000 0.020000 0.027000" rpy="-0.000000 -1.570796 0.000000"/>
    <axis xyz="1 0 0"/>
    <limit lower="-2.07" upper="2.07" effort="50" velocity="2.0"/>
  </joint>
  <joint name="arm_right_6_joint" type="revolute">
    <parent link="arm_right_5_link"/>
    <child link="arm_right_6_link"/>
    <origin xyz="0.000000 0.000000 0.150000" rpy="-1.570796 -1.570796 0.000000"/>
    <axis xyz="1 0 0"/>
    <limit lower="-1.39" upper="1.39" effort="50" velocity="2.0"/>
  </joint>
  <joint name="arm_right_7_joint" type="revolute">
    <parent link="arm_right_6_link"/>
    <child link="arm_right_7_link"/>
    <origin xyz="0.000000 0.000000 0.000000" rpy="1.570796 0.000000 1.570796"/>
    <axis xyz="1 0 0"/>
    <limit lower="-2.07" upper="2.07" effort="50" velocity="2.0"/>
  </joint>
  <joint name="arm_right_tool_joint" type="fixed">
    <parent link="arm_right_7_link"/>
    <child link="arm_right_tool_link"/>
    <origin xyz="0.000000 0.000000 0.057300" rpy="-1.570796 -1.570796 0.000000"/>
  </joint>
</robot>